<?xml version="1.0"?>
<robot name="eufs" xmlns:xacro="http://www.ros.org/wiki/xacro">

   
  <!-- Include Ouster-URDF macro -->
  <xacro:include filename="$(find arg_devbot_description)/urdf/sensors/ouster.urdf.xacro"/>


  <!-- Robot mechanical parameters -->

  <!-- BASE FOOTPRINT -->
  <link name="devbot/base_footprint">
    <inertial>
      <mass value="125.0" />
      <origin xyz="0 0 0" />
      <inertia  ixx="1.391" ixy="0.004"  ixz="0.0"  iyy="6.853"  iyz="0.0"  izz="6.125" />
    </inertial>
    <visual>
      <origin xyz="0 0 0" rpy="0 0 0" />
       <geometry>
         <box size="0.001 0.001 0.001" />
       </geometry>
     </visual>
   </link>

  <joint name="devbot/base_footprint_joint" type="fixed">
    <origin xyz="0 0 -0.345" rpy="0 0 0" />  
    <parent link="base_link"/>
    <child link="devbot/base_footprint" />
  </joint>

  <!-- BASE_LINK -->
  <link name="base_link">
    <visual>
       <origin xyz="0.56 0 -0.09" rpy="0 0 0" />
       <geometry>
	     <mesh filename="package://arg_devbot_description/meshes/DevbotV2.dae"/>
       </geometry>
    </visual>
    <collision>
       <origin xyz="0.56 0 -0.09" rpy="0 0 0 " />
       <geometry>
         <mesh filename="package://arg_devbot_description/meshes/DevbotV2.dae"/>
       </geometry>
    </collision>
  </link>

  <!-- COG -->
  <link name="devbot/COG"/>
  <joint name="cog_joint" type="fixed">
    <origin xyz="1.17 0.0 0.0" rpy="0.0 0.0 0.0" />
    <parent link="base_link" />
    <child link="devbot/COG" />
  </joint>

  <!-- GPS -->
  <link name="devbot/gps"/>
  <joint name="gps_joint" type="fixed">
    <origin xyz="1.232 -0.1 -0.056" rpy="0.0 0.0 0.0" />
    <parent link="base_link" />
    <child link="devbot/gps" />
  </joint>

  <!-- Lidar TOP -->
  <xacro:LidarOuster name="lidar_top/os_sensor" parent="base_link" lidar_link="lidar_top/os_lidar" imu_link="lidar_top/os_imu" >
    <origin xyz="1.288 0 0.708" rpy="0 0 -0.111" />
  </xacro:LidarOuster>
  
  
  <!-- Corner FRONT LEFT-->
  <link name="devbot/corner_fl"/>
  <joint name="devbot_corner_fl_joint" type="fixed">
    <origin xyz="3.91 1.0 -0.345" rpy="0.0 0.0 3.141" />
    <parent link="base_link" />
    <child link="devbot/corner_fl" />
  </joint>

  <!-- Corner FRONT RIGHT-->
  <link name="devbot/corner_fr"/>
  <joint name="devbot_corner_fr_joint" type="fixed">
    <origin xyz="3.91 -1.0 -0.345" rpy="0.0 0.0 1.570" />
    <parent link="base_link" />
    <child link="devbot/corner_fr" />
  </joint>

  <!-- Corner REAR LEFT-->
  <link name="devbot/corner_rl"/>
  <joint name="devbot_corner_rl_joint" type="fixed">
    <origin xyz="-0.91 1.0 -0.345" rpy="0.0 0.0 -1.570" />
    <parent link="base_link" />
    <child link="devbot/corner_rl" />
  </joint>

  <!-- Corner REAR RIGHT-->
  <link name="devbot/corner_rr"/>
  <joint name="devbot_corner_rr_joint" type="fixed">
    <origin xyz="-0.91 -1.0 -0.345" rpy="0.0 0.0 0.0" />
    <parent link="base_link" />
    <child link="devbot/corner_rr" />
  </joint>

    <link name="devbot/steer_fl">
      <inertial>
        <origin xyz="0 0 0" rpy="0 0 0"/>
        <mass value="1.0"/>
        <inertia ixx="0.037227" ixy="0" ixz="0" iyy="0.04" iyz="0" izz="0.06"/>
      </inertial>
    </link>

    <link name="devbot/steer_fr">
      <inertial>
        <origin xyz="0 0 0" rpy="0 0 0"/>
        <mass value="1.0"/>
        <inertia ixx="0.037227" ixy="0" ixz="0" iyy="0.04" iyz="0" izz="0.06"/>
      </inertial>
    </link>

  <link name="devbot/wheel_fl">
      <inertial>
        <origin xyz="0 0 0" rpy="0 -3.141593 0"/>
        <mass value="10.0"/>
        <inertia ixx="0.305583" ixy="0" ixz="0" iyy="0.305583" iyz="0" izz="0.5445"/>
      </inertial>
      <collision name="devbot/wheel_fl_collision">
        <origin xyz="0 0 0" rpy="0 -3.141593 0"/>
        <geometry>
          <cylinder radius="0.325" length="0.260"/>
        </geometry>
      </collision>
    </link>

    <link name="devbot/wheel_fr">
      <inertial>
        <origin xyz="0 0 0" rpy="0 3.141593 0"/>
        <mass value="10.0"/>
        <inertia ixx="0.305583" ixy="0" ixz="0" iyy="0.305583" iyz="0" izz="0.5445"/>
      </inertial>
      <collision name="devbot/wheel_fr_collision">
        <origin xyz="0 0 -0.1035" rpy="0 3.141593 0"/>
        <geometry>
          <cylinder radius="0.325" length="0.260"/>
        </geometry>
      </collision>
    </link>

    <link name="devbot/wheel_rl">
      <inertial>
        <origin xyz="0 0 -0.021117" rpy="0 3.141593 0"/>
        <mass value="10.0"/>
        <inertia ixx="0.305583" ixy="0" ixz="0" iyy="0.305583" iyz="0" izz="0.5445"/>
      </inertial>
      <collision name="devbot/wheel_rl_collision">
        <origin xyz="0 0 -0.021118" rpy="0 3.141593 0"/>
        <geometry>
          <cylinder radius="0.345" length="0.305"/>
        </geometry>
      </collision>
    </link>

    <link name="devbot/wheel_rr">
      <inertial>
        <origin xyz="0 0 0.0205" rpy="0 3.141593 0"/>
        <mass value="10.0"/>
        <inertia ixx="0.305583" ixy="0" ixz="0" iyy="0.305583" iyz="0" izz="0.5445"/>
      </inertial>
      <collision name="devbot/wheel_rr_collision">
        <origin xyz="0 0 0.0205" rpy="0 3.141593 0"/>
        <geometry>
          <cylinder radius="0.345" length="0.305"/>
        </geometry>
      </collision>
    </link>



    <joint name="devbot/steer_fl_joint" type="revolute">
      <origin xyz="2.9 0.7905 -0.02" rpy="0 0 0"/>
      <parent link="base_link"/>
      <child link="devbot/steer_fl"/>
      <axis xyz="0 0 1.0"/>
      <limit lower="-0.6" upper="0.6" effort="0" velocity="0"/>
    </joint>

    <joint name="devbot/steer_fr_joint" type="revolute">
      <origin xyz="2.9 -0.7905 -0.02" rpy="0 0 0"/>
      <parent link="base_link"/>
      <child link="devbot/steer_fr"/>
      <axis xyz="0 0 1.0"/>
      <limit lower="-0.6" upper="0.6" effort="0" velocity="0"/>
    </joint>

    <joint name="devbot/wheel_fl_joint" type="continuous">
      <origin xyz="0 0 0" rpy="1.570796 0 -3.141593"/>
      <parent link="devbot/steer_fl"/>
      <child link="devbot/wheel_fl"/>
      <axis xyz="0 0 1.0"/>
      <limit effort="0" velocity="22.0"/>
    </joint>

    <joint name="devbot/wheel_fr_joint" type="continuous">
      <origin xyz="0 0 0" rpy="1.570796 0 -3.141593"/>
      <parent link="devbot/steer_fr"/>
      <child link="devbot/wheel_fr"/>
      <axis xyz="0 0 1.0"/>
      <limit effort="0" velocity="22.0"/>
    </joint>

    <joint name="devbot/wheel_rl_joint" type="continuous">
      <origin xyz="0 0.7405 0" rpy="1.570796 0 -3.141593"/>
      <parent link="base_link"/>
      <child link="devbot/wheel_rl"/>
      <axis xyz="0 0 1.0"/>
      <limit effort="5000.0" velocity="22.0"/>
    </joint>

    <joint name="devbot/wheel_rr_joint" type="continuous">
      <origin xyz="0 -0.7405 0" rpy="1.570796 0 -3.141593"/>
      <parent link="base_link"/>
      <child link="devbot/wheel_rr"/>
      <axis xyz="0 0 1.0"/>
      <limit effort="5000.0" velocity="22.0"/>
    </joint>

</robot>

